Workbook
Name criado: 'BASE CONE'!$J:$J
Name dtc: 'BASE CONE'!$K:$K
Name Item: 'BASE CONE'!$A:$A
Name jornada: 'BASE CONE'!$T:$T
Name release: 'BASE CONE'!$U:$U
Name resolvido: 'BASE CONE'!$M:$M
Name status: 'BASE CONE'!$E:$E
Name time: 'BASE CONE'!$F:$F

Sheet Visão Geral
J2: Times Locavia | K2: Melhor caso | M2: Pior caso | O2: QA
J3: ID.4 | K3: =INDEX(#REF!,MATCH(0,#REF!,0)) -> #REF! | L3: 7 | M3: =INDEX(#REF!,MATCH(0,#REF!,0)) -> #REF! | N3: =L3 -> 7 | O3: 46066 | P3: -3
J4: Scania | K4: =INDEX(#REF!,MATCH(0,#REF!,0)) -> #REF! | L4: 2 | M4: =INDEX(#REF!,MATCH(0,#REF!,0)) -> #REF! | N4: =L4 -> 2 | O4: Produção
J5: Fusca | K5: =INDEX(#REF!,MATCH(0,#REF!,0)) -> #REF! | L5: 5 | M5: =INDEX(#REF!,MATCH(0,#REF!,0)) -> #REF! | N5: =L5 -> 5 | O5: 46092 | P5: -3
J6: Optimus | K6: =INDEX(#REF!,MATCH(0,#REF!,0)) -> #REF! | L6: 8 | M6: =INDEX(#REF!,MATCH(0,#REF!,0)) -> #REF! | N6: =L6 -> 8
J7: Jetta | K7: =INDEX(#REF!,MATCH(0,#REF!,0)) -> #REF! | L7: 3 | M7: =INDEX(#REF!,MATCH(0,#REF!,0)) -> #REF! | N7: =L7 -> 3
J8: Brasília | K8: =INDEX(#REF!,MATCH(0,#REF!,0)) -> #REF! | L8: 1 | M8: =INDEX(#REF!,MATCH(0,#REF!,0)) -> #REF! | N8: =L8 -> 1
J9: Amarok | K9: =INDEX(#REF!,MATCH(0,#REF!,0)) -> #REF! | L9: 4 | M9: =INDEX(#REF!,MATCH(0,#REF!,0)) -> #REF! | N9: =L9 -> 4
J10: Tiguan | K10: =INDEX(#REF!,MATCH(0,#REF!,0)) -> #REF! | L10: 6 | M10: =INDEX(#REF!,MATCH(0,#REF!,0)) -> #REF! | N10: =L10 -> 6
J11: Up | K11: =INDEX(#REF!,MATCH(0,#REF!,0)) -> #REF! | L11: 9 | M11: =INDEX(#REF!,MATCH(0,#REF!,0)) -> #REF! | N11: =L11 -> 9
J12: Gol | K12: =INDEX(#REF!,MATCH(0,#REF!,0)) -> #REF! | L12: 10 | M12: =INDEX(#REF!,MATCH(0,#REF!,0)) -> #REF! | N12: 10
J13: Taos | K13: =INDEX(#REF!,MATCH(0,#REF!,0)) -> #REF! | L13: 11 | M13: =INDEX(#REF!,MATCH(0,#REF!,0)) -> #REF! | N13: 11
J14: Santana | K14: =INDEX(#REF!,MATCH(0,#REF!,0)) -> #REF! | L14: 12 | M14: =INDEX(#REF!,MATCH(0,#REF!,0)) -> #REF! | N14: 12
J15: Arquitetura | K15: =INDEX(#REF!,MATCH(0,#REF!,0)) -> #REF! | L15: 13 | M15: =INDEX(#REF!,MATCH(0,#REF!,0)) -> #REF! | N15: 13

Sheet Visão O4R1
J2: Times Locavia | K2: Melhor caso | M2: Pior caso | O2: QA
J3: ID.4 | K3: =INDEX(#REF!,MATCH(0,#REF!,0)) -> #REF! | L3: 7 | M3: =INDEX(#REF!,MATCH(0,#REF!,0)) -> #REF! | N3: =L3 -> 7 | O3: 46020 | P3: -3
J4: Scania | K4: =INDEX(#REF!,MATCH(0,#REF!,0)) -> #REF! | L4: 2 | M4: =INDEX(#REF!,MATCH(0,#REF!,0)) -> #REF! | N4: =L4 -> 2 | O4: Produção
J5: Fusca | K5: =INDEX(#REF!,MATCH(0,#REF!,0)) -> #REF! | L5: 5 | M5: =INDEX(#REF!,MATCH(0,#REF!,0)) -> #REF! | N5: =L5 -> 5 | O5: 46034 | P5: -3
J6: Optimus | K6: =INDEX(#REF!,MATCH(0,#REF!,0)) -> #REF! | L6: 8 | M6: =INDEX(#REF!,MATCH(0,#REF!,0)) -> #REF! | N6: =L6 -> 8
J7: Jetta | K7: =INDEX(#REF!,MATCH(0,#REF!,0)) -> #REF! | L7: 3 | M7: =INDEX(#REF!,MATCH(0,#REF!,0)) -> #REF! | N7: =L7 -> 3
J8: Brasília | K8: =INDEX(#REF!,MATCH(0,#REF!,0)) -> #REF! | L8: 1 | M8: =INDEX(#REF!,MATCH(0,#REF!,0)) -> #REF! | N8: =L8 -> 1
J9: Amarok (Plano B) | K9: =INDEX(#REF!,MATCH(0,#REF!,0)) -> #REF! | L9: 4 | M9: =INDEX(#REF!,MATCH(0,#REF!,0)) -> #REF! | N9: =L9 -> 4
J10: Tiguan | K10: =INDEX(#REF!,MATCH(0,#REF!,0)) -> #REF! | L10: 6 | M10: =INDEX(#REF!,MATCH(0,#REF!,0)) -> #REF! | N10: =L10 -> 6
J11: Up | K11: =INDEX(#REF!,MATCH(0,#REF!,0)) -> #REF! | L11: 9 | M11: =INDEX(#REF!,MATCH(0,#REF!,0)) -> #REF! | N11: =L11 -> 9
J12: Gol | K12: =INDEX(#REF!,MATCH(0,#REF!,0)) -> #REF! | L12: 10 | M12: =INDEX(#REF!,MATCH(0,#REF!,0)) -> #REF! | N12: 10
J13: Taos | K13: =INDEX(#REF!,MATCH(0,#REF!,0)) -> #REF! | L13: 11 | M13: =INDEX(#REF!,MATCH(0,#REF!,0)) -> #REF! | N13: 11
J14: Santana | K14: =INDEX(#REF!,MATCH(0,#REF!,0)) -> #REF! | L14: 12 | M14: =INDEX(#REF!,MATCH(0,#REF!,0)) -> #REF! | N14: 12
J15: Arquitetura | K15: =INDEX(#REF!,MATCH(0,#REF!,0)) -> #REF! | L15: 13 | M15: =INDEX(#REF!,MATCH(0,#REF!,0)) -> #REF! | N15: 13
J16: Tera | K16: =INDEX(#REF!,MATCH(0,#REF!,0)) -> #REF! | L16: 14 | M16: =INDEX(#REF!,MATCH(0,#REF!,0)) -> #REF! | N16: 14

Sheet Modelo Estrutura
A1: Cone: baseado na nossa vazão, chegaremos na data alvo? O que cabe até data alvo?
B2: Quantidade de Épicos | C2: 1 | D2: Épicos | E2: considerar apenas os épicos que estão no mapa de release
B3: Qtd de Story / Task / Bug / Spike | C3: 13 | D3: Story / Tarefa / Bug / Spike | E3: considerar o trabalho de todos os integrantes do time, inclsuive tasks de dívidas técnicas e automação
B4: Data início | C4: 45936 | D4: Primeria sprint da release
B5: Data fim esperada | C5: 46014 | D5: Data entregada release
B6: Melhor cenário | C6: 4 | D6: itens por semana | E6: considerar sempre as ultimas 4 sprints para atualizar os números
B7: Pior cenário | C7: 1 | D7: itens por semana | E7: considerar sempre as ultimas 4 sprints para atualizar os números
B8: Velocidade necessária | C8: 3 | D8: itens por semana
B9: Acompanhar a cada | C9: 7 | D9: dias
B11: Data do Início da Semana | C11: Se seguirmos nossa melhor vazão, quando entregamos? | D11: Se seguirmos nossa pior vazão, quando entregamos? | E11: Vazão ideal para atender à data | F11: Itens da sprint anterior que não foram concluídos | G11: Itens que entram em sprint pela primeira vez | H11: Itens que entraram na Sprint depois do planejamento, mas não são "Fura fila" | I11: Itens Fura-Fila que apareceram ao longo da Sprint | J11: Itens entregues na Sprint | K11: Itens que chegaram no backlog do time ao longo da semana, mas não na sprint | L11: Observações adicionais
B12: Não editar esses campos | G12: Preencher com os dados de cada semana
A13: Sprint | B13: Semana | C13: A fazer (melhor cenário) | D13: A fazer (pior cenário) | E13: A fazer (valocidade necessária) | F13: Itens Transbordo | G13: Itens Planejados (Planning) | H13: Itens não planejados na sprint | I13: (+) Expedite | J13: Realizado | K13: (+)(-) Escopo pro time | L13: OBSERVAÇÕES
B14: =C4 -> 45936 | C14: =C3 -> 13 | D14: =C3 -> 13 | E14: =C3 -> 13 | F14: 0 | G14: 3 | H14: 1 | I14: 1 | J14: 0 | K14: 5
B15: =B14+$C$9 -> 45943 | C15: =IF(OR(C14="",C14=0),"",IF(ISBLANK($J14),IF(C14+$K14+$I14-$C$6<=0,IF(AND(C14>0,C14<>""),0,""),C14+$K14+$I14-$C$6),IF((C14-$J14)+$K14+$I14<=0,IF(AND(C14>0,C14<>""),0,""),(C14-$J14)+$K14+$I14))) -> 19 | D15: =IF(OR(D14="",D14=0),"",IF(ISBLANK($J14),IF(D14+$K14+$I14-$C$7<=0,IF(AND(D14>0,D14<>""),0,""),D14+$K14+$I14-$C$7),IF((D14-$J14)+$K14+$I14<=0,IF(AND(D14>0,D14<>""),0,""),(D14-$J14)+$K14+$I14))) -> 19 | E15: =IF(OR(E14="",E14=0),"",IF(ISBLANK($J14),IF(E14+$K14+$I14-$C$8<=0,IF(AND(E14>0,E14<>""),0,""),E14+$K14+$I14-$C$8),IF((E14-$J14)+$K14+$I14<=0,IF(AND(E14>0,E14<>""),0,""),(E14-$J14)+$K14+$I14))) -> 19 | F15: =IF(J14="","",IF(G14+F14+H14+I14-J14<0,0,G14+F14+H14+I14-J14)) -> 5 | G15: 0 | H15: -1 | I15: 1 | J15: 1 | L15: Começamos entrega X
B16: =B15+$C$9 -> 45950 | C16: =IF(OR(C15="",C15=0),"",IF(ISBLANK(J15),IF(C15+K15+I15-$C$6<=0,IF(AND(C15>0,C15<>""),0,""),C15+K15+I15-$C$6),IF((C15-J15)+K15+I15<=0,IF(AND(C15>0,C15<>""),0,""),(C15-J15)+K15+I15))) -> 19 | D16: =IF(OR(D15="",D15=0),"",IF(ISBLANK($J15),IF(D15+$K15+$I15-$C$7<=0,IF(AND(D15>0,D15<>""),0,""),D15+$K15+$I15-$C$7),IF((D15-$J15)+$K15+$I15<=0,IF(AND(D15>0,D15<>""),0,""),(D15-$J15)+$K15+$I15))) -> 19 | E16: =IF(OR(E15="",E15=0),"",IF(ISBLANK($J15),IF(E15+$K15+$I15-$C$8<=0,IF(AND(E15>0,E15<>""),0,""),E15+$K15+$I15-$C$8),IF((E15-$J15)+$K15+$I15<=0,IF(AND(E15>0,E15<>""),0,""),(E15-$J15)+$K15+$I15))) -> 19 | F16: =IF(J15="","",IF(G15+F15+H15+I15-J15<0,0,G15+F15+H15+I15-J15)) -> 4 | G16: 3 | J16: 0
B17: =B16+$C$9 -> 45957 | C17: =IF(OR(C16="",C16=0),"",IF(ISBLANK(J16),IF(C16+K16+I16-$C$6<=0,IF(AND(C16>0,C16<>""),0,""),C16+K16+I16-$C$6),IF((C16-J16)+K16+I16<=0,IF(AND(C16>0,C16<>""),0,""),(C16-J16)+K16+I16))) -> 19 | D17: =IF(OR(D16="",D16=0),"",IF(ISBLANK($J16),IF(D16+$K16+$I16-$C$7<=0,IF(AND(D16>0,D16<>""),0,""),D16+$K16+$I16-$C$7),IF((D16-$J16)+$K16+$I16<=0,IF(AND(D16>0,D16<>""),0,""),(D16-$J16)+$K16+$I16))) -> 19 | E17: =IF(OR(E16="",E16=0),"",IF(ISBLANK($J16),IF(E16+$K16+$I16-$C$8<=0,IF(AND(E16>0,E16<>""),0,""),E16+$K16+$I16-$C$8),IF((E16-$J16)+$K16+$I16<=0,IF(AND(E16>0,E16<>""),0,""),(E16-$J16)+$K16+$I16))) -> 19 | F17: =IF(J16="","",IF(G16+F16+H16+I16-J16<0,0,G16+F16+H16+I16-J16)) -> 7 | J17: 2 | K17: 7
B18: =B17+$C$9 -> 45964 | C18: =IF(OR(C17="",C17=0),"",IF(ISBLANK(J17),IF(C17+K17+I17-$C$6<=0,IF(AND(C17>0,C17<>""),0,""),C17+K17+I17-$C$6),IF((C17-J17)+K17+I17<=0,IF(AND(C17>0,C17<>""),0,""),(C17-J17)+K17+I17))) -> 24 | D18: =IF(OR(D17="",D17=0),"",IF(ISBLANK($J17),IF(D17+$K17+$I17-$C$7<=0,IF(AND(D17>0,D17<>""),0,""),D17+$K17+$I17-$C$7),IF((D17-$J17)+$K17+$I17<=0,IF(AND(D17>0,D17<>""),0,""),(D17-$J17)+$K17+$I17))) -> 24 | E18: =IF(OR(E17="",E17=0),"",IF(ISBLANK($J17),IF(E17+$K17+$I17-$C$8<=0,IF(AND(E17>0,E17<>""),0,""),E17+$K17+$I17-$C$8),IF((E17-$J17)+$K17+$I17<=0,IF(AND(E17>0,E17<>""),0,""),(E17-$J17)+$K17+$I17))) -> 24 | F18: =IF(J17="","",IF(G17+F17+H17+I17-J17<0,0,G17+F17+H17+I17-J17)) -> 5 | J18: 1
B19: =B18+$C$9 -> 45971 | C19: =IF(OR(C18="",C18=0),"",IF(ISBLANK(J18),IF(C18+K18+I18-$C$6<=0,IF(AND(C18>0,C18<>""),0,""),C18+K18+I18-$C$6),IF((C18-J18)+K18+I18<=0,IF(AND(C18>0,C18<>""),0,""),(C18-J18)+K18+I18))) -> 23 | D19: =IF(OR(D18="",D18=0),"",IF(ISBLANK($J18),IF(D18+$K18+$I18-$C$7<=0,IF(AND(D18>0,D18<>""),0,""),D18+$K18+$I18-$C$7),IF((D18-$J18)+$K18+$I18<=0,IF(AND(D18>0,D18<>""),0,""),(D18-$J18)+$K18+$I18))) -> 23 | E19: =IF(OR(E18="",E18=0),"",IF(ISBLANK($J18),IF(E18+$K18+$I18-$C$8<=0,IF(AND(E18>0,E18<>""),0,""),E18+$K18+$I18-$C$8),IF((E18-$J18)+$K18+$I18<=0,IF(AND(E18>0,E18<>""),0,""),(E18-$J18)+$K18+$I18))) -> 23 | F19: =IF(J18="","",IF(G18+F18+H18+I18-J18<0,0,G18+F18+H18+I18-J18)) -> 4
B20: =B19+$C$9 -> 45978 | C20: =IF(OR(C19="",C19=0),"",IF(ISBLANK(J19),IF(C19+K19+I19-$C$6<=0,IF(AND(C19>0,C19<>""),0,""),C19+K19+I19-$C$6),IF((C19-J19)+K19+I19<=0,IF(AND(C19>0,C19<>""),0,""),(C19-J19)+K19+I19))) -> 19 | D20: =IF(OR(D19="",D19=0),"",IF(ISBLANK($J19),IF(D19+$K19+$I19-$C$7<=0,IF(AND(D19>0,D19<>""),0,""),D19+$K19+$I19-$C$7),IF((D19-$J19)+$K19+$I19<=0,IF(AND(D19>0,D19<>""),0,""),(D19-$J19)+$K19+$I19))) -> 22 | E20: =IF(OR(E19="",E19=0),"",IF(ISBLANK($J19),IF(E19+$K19+$I19-$C$8<=0,IF(AND(E19>0,E19<>""),0,""),E19+$K19+$I19-$C$8),IF((E19-$J19)+$K19+$I19<=0,IF(AND(E19>0,E19<>""),0,""),(E19-$J19)+$K19+$I19))) -> 20 | F20: =IF(J19="","",IF(G19+F19+H19+I19-J19<0,0,G19+F19+H19+I19-J19))
B21: =B20+$C$9 -> 45985 | C21: =IF(OR(C20="",C20=0),"",IF(ISBLANK(J20),IF(C20+K20+I20-$C$6<=0,IF(AND(C20>0,C20<>""),0,""),C20+K20+I20-$C$6),IF((C20-J20)+K20+I20<=0,IF(AND(C20>0,C20<>""),0,""),(C20-J20)+K20+I20))) -> 15 | D21: =IF(OR(D20="",D20=0),"",IF(ISBLANK($J20),IF(D20+$K20+$I20-$C$7<=0,IF(AND(D20>0,D20<>""),0,""),D20+$K20+$I20-$C$7),IF((D20-$J20)+$K20+$I20<=0,IF(AND(D20>0,D20<>""),0,""),(D20-$J20)+$K20+$I20))) -> 21 | E21: =IF(OR(E20="",E20=0),"",IF(ISBLANK($J20),IF(E20+$K20+$I20-$C$8<=0,IF(AND(E20>0,E20<>""),0,""),E20+$K20+$I20-$C$8),IF((E20-$J20)+$K20+$I20<=0,IF(AND(E20>0,E20<>""),0,""),(E20-$J20)+$K20+$I20))) -> 17 | F21: =IF(J20="","",IF(G20+F20+H20+I20-J20<0,0,G20+F20+H20+I20-J20))
B22: =B21+$C$9 -> 45992 | C22: =IF(OR(C21="",C21=0),"",IF(ISBLANK(J21),IF(C21+K21+I21-$C$6<=0,IF(AND(C21>0,C21<>""),0,""),C21+K21+I21-$C$6),IF((C21-J21)+K21+I21<=0,IF(AND(C21>0,C21<>""),0,""),(C21-J21)+K21+I21))) -> 11 | D22: =IF(OR(D21="",D21=0),"",IF(ISBLANK($J21),IF(D21+$K21+$I21-$C$7<=0,IF(AND(D21>0,D21<>""),0,""),D21+$K21+$I21-$C$7),IF((D21-$J21)+$K21+$I21<=0,IF(AND(D21>0,D21<>""),0,""),(D21-$J21)+$K21+$I21))) -> 20 | E22: =IF(OR(E21="",E21=0),"",IF(ISBLANK($J21),IF(E21+$K21+$I21-$C$8<=0,IF(AND(E21>0,E21<>""),0,""),E21+$K21+$I21-$C$8),IF((E21-$J21)+$K21+$I21<=0,IF(AND(E21>0,E21<>""),0,""),(E21-$J21)+$K21+$I21))) -> 14 | F22: =IF(J21="","",IF(G21+F21+H21+I21-J21<0,0,G21+F21+H21+I21-J21))
B23: =B22+$C$9 -> 45999 | C23: =IF(OR(C22="",C22=0),"",IF(ISBLANK(J22),IF(C22+K22+I22-$C$6<=0,IF(AND(C22>0,C22<>""),0,""),C22+K22+I22-$C$6),IF((C22-J22)+K22+I22<=0,IF(AND(C22>0,C22<>""),0,""),(C22-J22)+K22+I22))) -> 7 | D23: =IF(OR(D22="",D22=0),"",IF(ISBLANK($J22),IF(D22+$K22+$I22-$C$7<=0,IF(AND(D22>0,D22<>""),0,""),D22+$K22+$I22-$C$7),IF((D22-$J22)+$K22+$I22<=0,IF(AND(D22>0,D22<>""),0,""),(D22-$J22)+$K22+$I22))) -> 19 | E23: =IF(OR(E22="",E22=0),"",IF(ISBLANK($J22),IF(E22+$K22+$I22-$C$8<=0,IF(AND(E22>0,E22<>""),0,""),E22+$K22+$I22-$C$8),IF((E22-$J22)+$K22+$I22<=0,IF(AND(E22>0,E22<>""),0,""),(E22-$J22)+$K22+$I22))) -> 11 | F23: =IF(J22="","",IF(G22+F22+H22+I22-J22<0,0,G22+F22+H22+I22-J22))
B24: =B23+$C$9 -> 46006 | C24: =IF(OR(C23="",C23=0),"",IF(ISBLANK(J23),IF(C23+K23+I23-$C$6<=0,IF(AND(C23>0,C23<>""),0,""),C23+K23+I23-$C$6),IF((C23-J23)+K23+I23<=0,IF(AND(C23>0,C23<>""),0,""),(C23-J23)+K23+I23))) -> 3 | D24: =IF(OR(D23="",D23=0),"",IF(ISBLANK($J23),IF(D23+$K23+$I23-$C$7<=0,IF(AND(D23>0,D23<>""),0,""),D23+$K23+$I23-$C$7),IF((D23-$J23)+$K23+$I23<=0,IF(AND(D23>0,D23<>""),0,""),(D23-$J23)+$K23+$I23))) -> 18 | E24: =IF(OR(E23="",E23=0),"",IF(ISBLANK($J23),IF(E23+$K23+$I23-$C$8<=0,IF(AND(E23>0,E23<>""),0,""),E23+$K23+$I23-$C$8),IF((E23-$J23)+$K23+$I23<=0,IF(AND(E23>0,E23<>""),0,""),(E23-$J23)+$K23+$I23))) -> 8 | F24: =IF(J23="","",IF(G23+F23+H23+I23-J23<0,0,G23+F23+H23+I23-J23))
B25: =B24+$C$9 -> 46013 | C25: =IF(OR(C24="",C24=0),"",IF(ISBLANK(J24),IF(C24+K24+I24-$C$6<=0,IF(AND(C24>0,C24<>""),0,""),C24+K24+I24-$C$6),IF((C24-J24)+K24+I24<=0,IF(AND(C24>0,C24<>""),0,""),(C24-J24)+K24+I24))) -> 0 | D25: =IF(OR(D24="",D24=0),"",IF(ISBLANK($J24),IF(D24+$K24+$I24-$C$7<=0,IF(AND(D24>0,D24<>""),0,""),D24+$K24+$I24-$C$7),IF((D24-$J24)+$K24+$I24<=0,IF(AND(D24>0,D24<>""),0,""),(D24-$J24)+$K24+$I24))) -> 17 | E25: =IF(OR(E24="",E24=0),"",IF(ISBLANK($J24),IF(E24+$K24+$I24-$C$8<=0,IF(AND(E24>0,E24<>""),0,""),E24+$K24+$I24-$C$8),IF((E24-$J24)+$K24+$I24<=0,IF(AND(E24>0,E24<>""),0,""),(E24-$J24)+$K24+$I24))) -> 5 | F25: =IF(J24="","",IF(G24+F24+H24+I24-J24<0,0,G24+F24+H24+I24-J24))
B26: =B25+$C$9 -> 46020 | C26: =IF(OR(C25="",C25=0),"",IF(ISBLANK(J25),IF(C25+K25+I25-$C$6<=0,IF(AND(C25>0,C25<>""),0,""),C25+K25+I25-$C$6),IF((C25-J25)+K25+I25<=0,IF(AND(C25>0,C25<>""),0,""),(C25-J25)+K25+I25))) | D26: =IF(OR(D25="",D25=0),"",IF(ISBLANK($J25),IF(D25+$K25+$I25-$C$7<=0,IF(AND(D25>0,D25<>""),0,""),D25+$K25+$I25-$C$7),IF((D25-$J25)+$K25+$I25<=0,IF(AND(D25>0,D25<>""),0,""),(D25-$J25)+$K25+$I25))) -> 16 | E26: =IF(OR(E25="",E25=0),"",IF(ISBLANK($J25),IF(E25+$K25+$I25-$C$8<=0,IF(AND(E25>0,E25<>""),0,""),E25+$K25+$I25-$C$8),IF((E25-$J25)+$K25+$I25<=0,IF(AND(E25>0,E25<>""),0,""),(E25-$J25)+$K25+$I25))) -> 2 | F26: =IF(J25="","",IF(G25+F25+H25+I25-J25<0,0,G25+F25+H25+I25-J25))
B27: =B26+$C$9 -> 46027 | C27: =IF(OR(C26="",C26=0),"",IF(ISBLANK(J26),IF(C26+K26+I26-$C$6<=0,IF(AND(C26>0,C26<>""),0,""),C26+K26+I26-$C$6),IF((C26-J26)+K26+I26<=0,IF(AND(C26>0,C26<>""),0,""),(C26-J26)+K26+I26))) | D27: =IF(OR(D26="",D26=0),"",IF(ISBLANK($J26),IF(D26+$K26+$I26-$C$7<=0,IF(AND(D26>0,D26<>""),0,""),D26+$K26+$I26-$C$7),IF((D26-$J26)+$K26+$I26<=0,IF(AND(D26>0,D26<>""),0,""),(D26-$J26)+$K26+$I26))) -> 15 | E27: =IF(OR(E26="",E26=0),"",IF(ISBLANK($J26),IF(E26+$K26+$I26-$C$8<=0,IF(AND(E26>0,E26<>""),0,""),E26+$K26+$I26-$C$8),IF((E26-$J26)+$K26+$I26<=0,IF(AND(E26>0,E26<>""),0,""),(E26-$J26)+$K26+$I26))) -> 0 | F27: =IF(J26="","",IF(G26+F26+H26+I26-J26<0,0,G26+F26+H26+I26-J26))
B28: =B27+$C$9 -> 46034 | C28: =IF(OR(C27="",C27=0),"",IF(ISBLANK(J27),IF(C27+K27+I27-$C$6<=0,IF(AND(C27>0,C27<>""),0,""),C27+K27+I27-$C$6),IF((C27-J27)+K27+I27<=0,IF(AND(C27>0,C27<>""),0,""),(C27-J27)+K27+I27))) | D28: =IF(OR(D27="",D27=0),"",IF(ISBLANK($J27),IF(D27+$K27+$I27-$C$7<=0,IF(AND(D27>0,D27<>""),0,""),D27+$K27+$I27-$C$7),IF((D27-$J27)+$K27+$I27<=0,IF(AND(D27>0,D27<>""),0,""),(D27-$J27)+$K27+$I27))) -> 14 | E28: =IF(OR(E27="",E27=0),"",IF(ISBLANK($J27),IF(E27+$K27+$I27-$C$8<=0,IF(AND(E27>0,E27<>""),0,""),E27+$K27+$I27-$C$8),IF((E27-$J27)+$K27+$I27<=0,IF(AND(E27>0,E27<>""),0,""),(E27-$J27)+$K27+$I27))) | F28: =IF(J27="","",IF(G27+F27+H27+I27-J27<0,0,G27+F27+H27+I27-J27))
B29: =B28+$C$9 -> 46041 | C29: =IF(OR(C28="",C28=0),"",IF(ISBLANK(J28),IF(C28+K28+I28-$C$6<=0,IF(AND(C28>0,C28<>""),0,""),C28+K28+I28-$C$6),IF((C28-J28)+K28+I28<=0,IF(AND(C28>0,C28<>""),0,""),(C28-J28)+K28+I28))) | D29: =IF(OR(D28="",D28=0),"",IF(ISBLANK($J28),IF(D28+$K28+$I28-$C$7<=0,IF(AND(D28>0,D28<>""),0,""),D28+$K28+$I28-$C$7),IF((D28-$J28)+$K28+$I28<=0,IF(AND(D28>0,D28<>""),0,""),(D28-$J28)+$K28+$I28))) -> 13 | E29: =IF(OR(E28="",E28=0),"",IF(ISBLANK($J28),IF(E28+$K28+$I28-$C$8<=0,IF(AND(E28>0,E28<>""),0,""),E28+$K28+$I28-$C$8),IF((E28-$J28)+$K28+$I28<=0,IF(AND(E28>0,E28<>""),0,""),(E28-$J28)+$K28+$I28))) | F29: =IF(J28="","",IF(G28+F28+H28+I28-J28<0,0,G28+F28+H28+I28-J28))
B30: =B29+$C$9 -> 46048 | C30: =IF(OR(C29="",C29=0),"",IF(ISBLANK(J29),IF(C29+K29+I29-$C$6<=0,IF(AND(C29>0,C29<>""),0,""),C29+K29+I29-$C$6),IF((C29-J29)+K29+I29<=0,IF(AND(C29>0,C29<>""),0,""),(C29-J29)+K29+I29))) | D30: =IF(OR(D29="",D29=0),"",IF(ISBLANK($J29),IF(D29+$K29+$I29-$C$7<=0,IF(AND(D29>0,D29<>""),0,""),D29+$K29+$I29-$C$7),IF((D29-$J29)+$K29+$I29<=0,IF(AND(D29>0,D29<>""),0,""),(D29-$J29)+$K29+$I29))) -> 12 | E30: =IF(OR(E29="",E29=0),"",IF(ISBLANK($J29),IF(E29+$K29+$I29-$C$8<=0,IF(AND(E29>0,E29<>""),0,""),E29+$K29+$I29-$C$8),IF((E29-$J29)+$K29+$I29<=0,IF(AND(E29>0,E29<>""),0,""),(E29-$J29)+$K29+$I29))) | F30: =IF(J29="","",IF(G29+F29+H29+I29-J29<0,0,G29+F29+H29+I29-J29))
... B54: =B53+$C$9 -> 46216 | C54: =IF(OR(C53="",C53=0),"",IF(ISBLANK(J53),IF(C53+K53+I53-$C$6<=0,IF(AND(C53>0,C53<>""),0,""),C53+K53+I53-$C$6),IF((C53-J53)+K53+I53<=0,IF(AND(C53>0,C53<>""),0,""),(C53-J53)+K53+I53))) | D54: =IF(OR(D53="",D53=0),"",IF(ISBLANK($J53),IF(D53+$K53+$I53-$C$7<=0,IF(AND(D53>0,D53<>""),0,""),D53+$K53+$I53-$C$7),IF((D53-$J53)+$K53+$I53<=0,IF(AND(D53>0,D53<>""),0,""),(D53-$J53)+$K53+$I53))) | E54: =IF(OR(E53="",E53=0),"",IF(ISBLANK($J53),IF(E53+$K53+$I53-$C$8<=0,IF(AND(E53>0,E53<>""),0,""),E53+$K53+$I53-$C$8),IF((E53-$J53)+$K53+$I53<=0,IF(AND(E53>0,E53<>""),0,""),(E53-$J53)+$K53+$I53))) | F54: =IF(J53="","",IF(G53+F53+H53+I53-J53<0,0,G53+F53+H53+I53-J53))
B111: =IF(B110="","",IF(B110+$C$9<=$C$5,B110+$C$9,"")) | C111: =IF(B111<>"",C110-$C$2/COUNT($B$17:$B$510),"")
B112: =IF(B111="","",IF(B111+$C$9<=$C$5,B111+$C$9,"")) | C112: =IF(B112<>"",C111-$C$2/COUNT($B$17:$B$510),"")
B113: =IF(B112="","",IF(B112+$C$9<=$C$5,B112+$C$9,"")) | C113: =IF(B113<>"",C112-$C$2/COUNT($B$17:$B$510),"")
B114: =IF(B113="","",IF(B113+$C$9<=$C$5,B113+$C$9,"")) | C114: =IF(B114<>"",C113-$C$2/COUNT($B$17:$B$510),"")
B115: =IF(B114="","",IF(B114+$C$9<=$C$5,B114+$C$9,"")) | C115: =IF(B115<>"",C114-$C$2/COUNT($B$17:$B$510),"")
B116: =IF(B115="","",IF(B115+$C$9<=$C$5,B115+$C$9,"")) | C116: =IF(B116<>"",C115-$C$2/COUNT($B$17:$B$510),"")
B117: =IF(B116="","",IF(B116+$C$9<=$C$5,B116+$C$9,"")) | C117: =IF(B117<>"",C116-$C$2/COUNT($B$17:$B$510),"")
B118: =IF(B117="","",IF(B117+$C$9<=$C$5,B117+$C$9,"")) | C118: =IF(B118<>"",C117-$C$2/COUNT($B$17:$B$510),"")
B119: =IF(B118="","",IF(B118+$C$9<=$C$5,B118+$C$9,"")) | C119: =IF(B119<>"",C118-$C$2/COUNT($B$17:$B$510),"")
B120: =IF(B119="","",IF(B119+$C$9<=$C$5,B119+$C$9,"")) | C120: =IF(B120<>"",C119-$C$2/COUNT($B$17:$B$510),"")
...

Sheet LEIA-ME
A1: Times | B1: ESCOPO | C1: Release
A2: UP | B2: WHATSAPP | C2: O4R
A3: NIVUS | B3: COMERCIAL | C3: O4R1
A4: TERA | B4: FATURAMENTO | C4: O4R2
A5: GOL | B5: VENDAS_ASSISTIDAS | C5: BAF
A6: OPTIMUS | B6: CONTRATOS | C6: BAF-QW
A7: AMAROK | B7: VENDAS_AUTO-ATENDIMENTO
A8: SANTANA | B8: RESSARCIMENTO
A9: TAOS | B9: CREDITO
A10: FUSCA | B10: SALESFORCE_PÓSVEND
A11: PARATI | B11: MIGRAÇÃO
A12: D.LAKE DOMINIO | B12: LAKE-ESTRUTURANTE
B13: RISCO
B14: COBRANÇA
B15: PROPOSTA

Sheet BASE CONE
A1: Tipo de item | B1: Chave da item | C1: ID da item | D1: Resumo | E1: Status | F1: Campo personalizado (Time) | G1: Campo personalizado (Jornada) | H1: Campo personalizado (Jornada)_1 | I1: Campo personalizado (Jornada)_2 | J1: Criado | K1: Campo personalizado (Data de Compromentimento) | L1: Campo personalizado (Start date) | M1: Resolvido | N1: Campo personalizado (Release) | O1: Campo personalizado (Release)_3 | P1: Campo personalizado (Release)_4 | Q1: Pai | R1: Chave pai | S1: Parent summary | T1: time | U1: release
A2: História | B2: WA-747 | C2: 156507 | D2: [Blip][AssinsCar.][Pós venda][Abertura de ocorrência] Meu Contrato, Documento - Solicitação de segunda via de contrato | E2: 1. Backlog | G2: WHATSAPP | J2: 46084.455 | K2: 45992.64 | L2: 45993 | N2: O4R1 | Q2: 156472 | R2: JAC-1528 | S2: [Blip][AssinsCar.] Pós venda - Abertura de ocorrência por área | T2: WHATSAPP;; | U2: O4R1;;
A3: Tarefa | B3: WA-696 | C3: 153376 | D3: [Blip][S&D Colab.][Comercial][Tabela de valor] Ajuste na tabela de preço - Lead e Renovação | E3: DESENV CONCLUIDO | F3: UP | G3: WHATSAPP | J3: 46066.617 | K3: 46066 | L3: 46066 | M3: 46076.447 | N3: O4R1 | Q3: 75650 | R3: WA-334 | S3: [Blip][S&D Colab.][R1] Comercial - Qualificação de Lead | T3: WHATSAPP;; | U3: O4R1;;
A4: História | B4: WA-676 | C4: 150279 | D4: [Blip][S&D Colab.][Pós vendas][Melhoria] Fluxo da FAQ perguntas e resposta | E4: 1. Backlog | G4: WHATSAPP | J4: 46056.426 | N4: O4R2 | Q4: 148376 | R4: WA-642 | S4: [Blip][S&D Colab.][R3] Pós venda - Abertura de ocorrência por área | T4: WHATSAPP;; | U4: O4R2;;
A5: História | B5: WA-669 | C5: 150097 | D5: [Blip][S&D Colab.][Click-tracker] Implementar studar a documentação da aplicação da Blip - Click Tracker | E5: DESENV CONCLUIDO | F5: UP | G5: WHATSAPP | J5: 46055.591 | K5: 46063.729 | L5: 46063 | M5: 46076.599 | N5: O4R2 | Q5: 148350 | R5: WA-624 | S5: [Blip][S&D Colab.][R3] [Cross] Estrutura do bot | T5: WHATSAPP;; | U5: O4R2;;
A6: Spike | B6: WA-660 | C6: 148789 | D6: [Blip][S&D Colaboradores][Comercial][Criação] UX -Desenho da jornada do no fluxo comercial - Qualificação de lead | E6: DESENV CONCLUIDO | F6: UP | G6: Comercial | J6: 46049.481 | K6: 46055 | L6: 46062 | M6: 46094.387 | N6: O4R2 | Q6: 148792 | R6: WA-661 | S6: [Blip][S&D Colab.][R3] Comercial - Qualificação de Lead | T6: Comercial;; | U6: O4R2;;
A7: Spike | B7: WA-659 | C7: 148788 | D7: [Blip][S&D Colaboradores][Comercial][Discovey] Melhoria no fluxo comercial - Qualificação de lead | E7: DESENV CONCLUIDO | F7: UP | G7: Comercial | J7: 46049.479 | K7: 46049 | L7: 46050 | M7: 46062.446 | N7: O4R2 | Q7: 148792 | R7: WA-661 | S7: [Blip][S&D Colab.][R3] Comercial - Qualificação de Lead | T7: Comercial;; | U7: O4R2;;
A8: História | B8: WA-656 | C8: 148784 | D8: [Blip][S&D Colab.][Comercial][Carrossel] Desenvolver o flow do componente do carrossel dentro da meta | E8: DESENV CONCLUIDO | F8: UP | G8: WHATSAPP | J8: 46049.471 | K8: 46073.52 | L8: 46073 | M8: 46076.592 | N8: O4R2 | Q8: 148350 | R8: WA-624 | S8: [Blip][S&D Colab.][R3] [Cross] Estrutura do bot | T8: WHATSAPP;; | U8: O4R2;;
A9: História | B9: WA-654 | C9: 148778 | D9: [Blip][S&D Colab.][Comercial][Carrossel][Flows] Converter a imagem para consumo do carrossel | E9: DESENV CONCLUIDO | F9: UP | G9: WHATSAPP | J9: 46049.458 | K9: 46076.8 | L9: 46076 | M9: 46083.43 | N9: O4R2 | Q9: 148350 | R9: WA-624 | S9: [Blip][S&D Colab.][R3] [Cross] Estrutura do bot | T9: WHATSAPP;; | U9: O4R2;;
A10: História | B10: WA-620 | C10: 148208 | D10: [Blip][S&D Colab.][Click-tracker][Estudo] Estudar a documentação da aplicação da Blip - Click Tracker | E10: DESENV CONCLUIDO | F10: UP | G10: WHATSAPP | J10: 46044.615 | K10: 46049.509 | L10: 46049 | M10: 46055.591 | N10: O4R2 | Q10: 148350 | R10: WA-624 | S10: [Blip][S&D Colab.][R3] [Cross] Estrutura do bot | T10: WHATSAPP;; | U10: O4R2;;
A11: História | B11: WA-618 | C11: 148197 | D11: [Blip][S&D Colab.][Pós vendas][Tag] Tagamento do fluxo de pos vendas | E11: DESENV CONCLUIDO | F11: UP | G11: Comercial | J11: 46044.592 | K11: 46044.885 | L11: 46044 | M11: 46073.39 | N11: O4R2 | Q11: 148376 | R11: WA-642 | S11: [Blip][S&D Colab.][R3] Pós venda - Abertura de ocorrência por área | T11: Comercial;; | U11: O4R2;;
A12: Tarefa | B12: WA-611 | C12: 145760 | D12: [Blip][S&D Colab.][Comercial][Tabela de valor] Ajuste na tabela de preço - Lead e Renovação | E12: DESENV CONCLUIDO | F12: UP | G12: WHATSAPP | J12: 46030.41 | K12: 46030.539 | L12: 46030.539 | M12: 46030.456 | N12: O4R1 | Q12: 75650 | R12: WA-334 | S12: [Blip][S&D Colab.][R1] Comercial - Qualificação de Lead | T12: WHATSAPP;; | U12: O4R1;;
A13: Tarefa | B13: WA-608 | C13: 141520 | D13: [Blip][S&D Colab.][Pós venda][Abertura de ocorrência] Fim de contrato - Devolução veículo - Ajuste | E13: DESENV CONCLUIDO | G13: WHATSAPP | J13: 46022.424 | K13: 46022 | L13: 46022 | M13: 46027.575 | N13: O4R1 | Q13: 75650 | R13: WA-334 | S13: [Blip][S&D Colab.][R1] Comercial - Qualificação de Lead | T13: WHATSAPP;; | U13: O4R1;;
A14: Tarefa | B14: WA-594 | C14: 140573 | D14: [Blip][S&D Colab.][Comercial][Renovação] Ajuste no fluxo - Incluir FAQ | E14: DESENV CONCLUIDO | F14: UP | G14: WHATSAPP | J14: 46020.469 | K14: 46020.758 | L14: 46020.758 | M14: 46030.631 | N14: O4R1 | Q14: 75650 | R14: WA-334 | S14: [Blip][S&D Colab.][R1] Comercial - Qualificação de Lead | T14: WHATSAPP;; | U14: O4R1;;
A15: Tarefa | B15: WA-593 | C15: 140572 | D15: [Blip][S&D Colab.][Comercial][Renovação] Ajuste no fluxo - Renovação de contrato | E15: DESENV CONCLUIDO | F15: UP | G15: WHATSAPP | J15: 46020.469 | K15: 46020.625 | L15: 46020.625 | M15: 46021.662 | N15: O4R1 | Q15: 75650 | R15: WA-334 | S15: [Blip][S&D Colab.][R1] Comercial - Qualificação de Lead | T15: WHATSAPP;; | U15: O4R1;;
A16: História | B16: WA-550 | C16: 129142 | D16: [Blip][S&D Colab.][Autosserviço] 2º via do boleto Investigação e correção de fluxos causando lentidão no fluxo de boleto (BLiP) | E16: DESENV CONCLUIDO | F16: UP | G16: WHATSAPP | J16: 46006.39 | K16: 46006.517 | L16: 46009 | M16: 46027.381 | N16: O4R1 | Q16: 75664 | R16: WA-348 | S16: [Blip][S&D Colab.][R1] Autosserviço - Financeiro - Solicitação boleto | T16: WHATSAPP;; | U16: O4R1;;
A17: Tarefa | B17: WA-543 | C17: 121717 | D17: [Blip][S&D Colab.] [Pós venda] Saudação inicial cliente sem placa | E17: DESENV CONCLUIDO | F17: UP | G17: WHATSAPP | J17: 45996.598 | K17: 46000.556 | L17: 46000 | M17: 46003.608 | N17: O4R1 | Q17: 71048 | R17: WA-274 | S17: [Blip][S&D Colab.][R1] Inicio bot | T17: WHATSAPP;; | U17: O4R1;;
A18: História | B18: WA-537 | C18: 119794 | D18: [Blip][S&D Colab.][Pós venda][Abertura de ocorrência] Desenvolvimento jornada Assistência 24h | E18: DESENV CONCLUIDO | F18: UP | G18: WHATSAPP | J18: 45994.514 | K18: 46014.503 | L18: 46015 | M18: 46031.485 | N18: O4R1 | Q18: 71032 | R18: WA-259 | S18: [Blip][S&D Colab.][R1] Pós venda - Abertura de ocorrência por área | T18: WHATSAPP;; | U18: O4R1;;
A19: História | B19: WA-534 | C19: 119790 | D19: [Blip][S&D Colab.][Pós venda][Abertura de ocorrência] Desenvolvimento jornada de manutenção | E19: DESENV CONCLUIDO | F19: UP | G19: WHATSAPP | J19: 45994.512 | K19: 46006.523 | L19: 46006 | M19: 46030.441 | N19: O4R1 | Q19: 71032 | R19: WA-259 | S19: [Blip][S&D Colab.][R1] Pós venda - Abertura de ocorrência por área | T19: WHATSAPP;; | U19: O4R1;;
A20: Spike | B20: WA-528 | C20: 118422 | D20: [Blip][S&D Colab.][Pós venda][Abertura de ocorrência] UX desenho da jornada - Assistência 24h | E20: DESENV CONCLUIDO | F20: UP | G20: Pos_venda | J20: 45993.801 | K20: 46006.535 | L20: 46009 | M20: 46010.725 | N20: O4R1 | Q20: 71032 | R20: WA-259 | S20: [Blip][S&D Colab.][R1] Pós venda - Abertura de ocorrência por área | T20: Pos_venda;; | U20: O4R1;;
A21: Spike | B21: WA-527 | C21: 118421 | D21: [Blip][S&D Colab.][Pós venda][Abertura de ocorrência] UX desenho da jornada - Manutenção | E21: DESENV CONCLUIDO | F21: UP | G21: Pos_venda | J21: 45993.8 | K21: 46001.833 | L21: 46001 | M21: 46006.378 | N21: O4R1 | Q21: 71032 | R21: WA-259 | S21: [Blip][S&D Colab.][R1] Pós venda - Abertura de ocorrência por área | T21: Pos_venda;; | U21: O4R1;;
A22: Tarefa | B22: WA-523 | C22: 116465 | D22: [Blip][S&D Colab.][Pós venda][Abertura de ocorrência] Debito técnico - Fluxo de Devolução de veiculo | E22: DESENV CONCLUIDO | F22: UP | G22: Pos_venda | J22: 45992.415 | K22: 45992.64 | L22: 45993 | M22: 46001.701 | N22: O4R1 | Q22: 71032 | R22: WA-259 | S22: [Blip][S&D Colab.][R1] Pós venda - Abertura de ocorrência por área | T22: Pos_venda;; | U22: O4R1;;
A23: Spike | B23: WA-504 | C23: 110041 | D23: [Blip][S&D Colab.][Comercial][Renovação] UX desenho da jornada -Renovação de contrato | E23: DESENV CONCLUIDO | F23: UP | G23: Pos_venda | J23: 45986.435 | K23: 45987.781 | L23: 45987.781 | M23: 45987.656 | N23: O4R1 | Q23: 71032 | R23: WA-259 | S23: [Blip][S&D Colab.][R1] Pós venda - Abertura de ocorrência por área | T23: Pos_venda;; | U23: O4R1;;
A24: Spike | B24: WA-503 | C24: 110040 | D24: [Blip][S&D Colab.][Pós venda][Abertura de ocorrência] UX desenho da jornada -Fim de contrato - 2 via de contrato | E24: DESENV CONCLUIDO | F24: UP | G24: Pos_venda | J24: 45986.435 | K24: 45999.747 | L24: 45999 | M24: 45999.622 | N24: O4R1 | Q24: 71032 | R24: WA-259 | S24: [Blip][S&D Colab.][R1] Pós venda - Abertura de ocorrência por área | T24: Pos_venda;; | U24: O4R1;;
A25: Tarefa | B25: WA-488 | C25: 103095 | D25: [S&D Colab.][4] Desenvolvimento arvore de saudação - Não recebeu o veiculo | E25: DESENV CONCLUIDO | F25: UP | G25: WHATSAPP | J25: 45979.441 | K25: 45985.499 | L25: 45985.499 | M25: 45989.385 | N25: O4R1 | Q25: 71032 | R25: WA-259 | S25: [Blip][S&D Colab.][R1] Pós venda - Abertura de ocorrência por área | T25: WHATSAPP;; | U25: O4R1;;
A26: Spike | B26: WA-473 | C26: 99291 | D26: [Blip][S&D Colab.][Pós venda][Abertura de ocorrência] UX desenho da jornada -Manutenção - Direcionamento para a ticket | E26: DESENV CONCLUIDO | F26: UP | G26: Pos_venda | J26: 45975.713 | K26: 45978.652 | L26: 45978.652 | M26: 45985.384 | N26: O4R1 | O26: Release_01 | Q26: 71032 | R26: WA-259 | S26: [Blip][S&D Colab.][R1] Pós venda - Abertura de ocorrência por área | T26: Pos_venda;; | U26: O4R1;Release_01;
A27: Spike | B27: WA-469 | C27: 99275 | D27: [Blip][S&D Colab.][HSM][Multas] Disparo endpoint de disparo | E27: DESENV CONCLUIDO | F27: UP | G27: Pos_venda | J27: 45975.687 | K27: 45978.753 | L27: 45979.715 | M27: 45982.668 | N27: O4R1 | Q27: 76935 | R27: WA-401 | S27: [Blip][S&D Colab.][R3] Multas - Disparos de mensagens ativas | T27: Pos_venda;; | U27: O4R1;;
A28: Spike | B28: WA-463 | C28: 94185 | D28: [Blip][S&D Colab.][Autosserviço] UX desenho da arvore de Solicitação segunda via da CRLV | E28: DESENV CONCLUIDO | F28: UP | G28: Migra_Blip | H28: Pos_venda | I28: WHATSAPP | J28: 45972.467 | K28: 45979.917 | L28: 45982.183 | M28: 45985.385 | N28: O4R1 | O28: Release_01 | Q28: 75678 | R28: WA-362 | S28: [Blip][S&D Colab.][R1] Autosserviço - Doc. do veículo - CRLV | T28: Migra_Blip;Pos_venda;WHATSAPP | U28: O4R1;Release_01;
A29: História | B29: WA-462 | C29: 90829 | D29: [Blip][S&D Colab.][Comercial][Renovação] Renovação de contrato | E29: DESENV CONCLUIDO | F29: UP | G29: WHATSAPP | J29: 45968.528 | K29: 45980.494 | L29: 45982.517 | M29: 45989.385 | N29: O4R1 | Q29: 75650 | R29: WA-334 | S29: [Blip][S&D Colab.][R1] Comercial - Qualificação de Lead | T29: WHATSAPP;; | U29: O4R1;;
A30: Spike | B30: WA-444 | C30: 89302 | D30: [Blip][S&D Colab.][Pós venda][Abertura de ocorrência] UX desenho da jornada - Fim de contrato - Devolução veículo | E30: DESENV CONCLUIDO | F30: UP | G30: Migra_Blip | H30: Pos_venda | I30: WHATSAPP | J30: 45967.864 | K30: 45978.651 | L30: 45978.651 | M30: 45985.384 | N30: O4R1 | Q30: 71032 | R30: WA-259 | S30: [Blip][S&D Colab.][R1] Pós venda - Abertura de ocorrência por área | T30: Migra_Blip;Pos_venda;WHATSAPP | U30: O4R1;;
A31: História | B31: WA-435 | C31: 89234 | D31: [Blip][S&D Colab.][Pós venda][Abertura de ocorrência] Perguntas frequentes | E31: DESENV CONCLUIDO | F31: UP | G31: Pos_venda | H31: WHATSAPP | J31: 45967.526 | K31: 45999.744 | L31: 46001 | M31: 46014.553 | N31: O4R1 | O31: Release_01 | Q31: 71032 | R31: WA-259 | S31: [Blip][S&D Colab.][R1] Pós venda - Abertura de ocorrência por área | T31: Pos_venda;WHATSAPP; | U31: O4R1;Release_01;
A32: Spike | B32: WA-418 | C32: 76971 | D32: [Blip][S&D Colab.][Autosserviço][Árvore de decisão] UX desenho da jornada solicitação do boleto | E32: DESENV CONCLUIDO | F32: UP | G32: Pos_venda | H32: WHATSAPP | J32: 45954.783 | K32: 45978.651 | L32: 45978.651 | M32: 45985.384 | N32: O4R1 | O32: Release_01 | Q32: 75664 | R32: WA-348 | S32: [Blip][S&D Colab.][R1] Autosserviço - Financeiro - Solicitação boleto | T32: Pos_venda;WHATSAPP; | U32: O4R1;Release_01;
A33: Spike | B33: WA-416 | C33: 76967 | D33: [Blip][S&D Colab.][Árvore de decisão] UX desenho da jornada - Pós venda menu inicial | E33: DESENV CONCLUIDO | F33: UP | G33: Migra_Blip | H33: Pos_venda | I33: WHATSAPP | J33: 45954.783 | K33: 45978.562 | L33: 45978.562 | M33: 45978.438 | N33: O4R1 | O33: Release_01 | Q33: 71032 | R33: WA-259 | S33: [Blip][S&D Colab.][R1] Pós venda - Abertura de ocorrência por área | T33: Migra_Blip;Pos_venda;WHATSAPP | U33: O4R1;Release_01;
A34: História | B34: WA-409 | C34: 76951 | D34: [Blip][S&D Colab.][HSM][Multas] Disparo de NIC - Responsabilidade Cliente | E34: 1. Backlog | G34: WHATSAPP | J34: 45954.767 | N34: O4R1 | Q34: 76935 | R34: WA-401 | S34: [Blip][S&D Colab.][R3] Multas - Disparos de mensagens ativas | T34: WHATSAPP;; | U34: O4R1;;
A35: História | B35: WA-407 | C35: 76947 | D35: [Blip][S&D Colab.][HSM][Multas] Disparo de NIP - Responsabilidade Locadora | E35: DESCARTADO | G35: WHATSAPP | J35: 45954.765 | M35: 46044.628 | N35: O4R1 | Q35: 76935 | R35: WA-401 | S35: [Blip][S&D Colab.][R3] Multas - Disparos de mensagens ativas | T35: WHATSAPP;; | U35: O4R1;;
A36: História | B36: WA-402 | C36: 76937 | D36: [Blip][S&D Colab.][HSM][Multas] Disparo de NAI/NIP BRF | E36: 1. Backlog | G36: WHATSAPP | J36: 45954.764 | N36: O4R1 | Q36: 76935 | R36: WA-401 | S36: [Blip][S&D Colab.][R3] Multas - Disparos de mensagens ativas | T36: WHATSAPP;; | U36: O4R1;;
A37: História | B37: WA-383 | C37: 75758 | D37: [Blip][S&D Colab.] Pós venda - Cadastro dos agentes de atendimento | E37: DESENV CONCLUIDO | F37: UP | G37: WHATSAPP | J37: 45953.518 | K37: 45972.637 | L37: 45972.637 | M37: 45972.512 | N37: O4R1 | O37: Release_01 | Q37: 74927 | R37: WA-333 | S37: [Blip][S&D Colab.][R1][Cross] Estrutura do bot | T37: WHATSAPP;; | U37: O4R1;Release_01;
A38: Spike | B38: WA-381 | C38: 75754 | D38: [Blip][S&D Colab.] Ativação dos números de homologação | E38: DESENV CONCLUIDO | F38: UP | G38: Migra_Blip | H38: WHATSAPP | J38: 45953.515 | K38: 45964.9 | L38: 45964 | M38: 45964.776 | N38: O4R1 | O38: Release_01 | Q38: 74927 | R38: WA-333 | S38: [Blip][S&D Colab.][R1][Cross] Estrutura do bot | T38: Migra_Blip;WHATSAPP; | U38: O4R1;Release_01;
A39: História | B39: WA-365 | C39: 75681 | D39: [Blip][S&D Colab.][Autosserviço] 2º via do boleto - Escritório de cobrança | E39: DESENV CONCLUIDO | F39: UP | G39: WHATSAPP | J39: 45952.783 | K39: 45994.514 | L39: 45994 | M39: 46009.65 | N39: O4R1 | O39: Release_01 | Q39: 75664 | R39: WA-348 | S39: [Blip][S&D Colab.][R1] Autosserviço - Financeiro - Solicitação boleto | T39: WHATSAPP;; | U39: O4R1;Release_01;
A40: História | B40: WA-364 | C40: 75680 | D40: [Blip][S&D Colab.][Autosserviço] Solicitação segunda via da CRLV | E40: DESENV CONCLUIDO | F40: UP | G40: WHATSAPP | J40: 45952.783 | K40: 45985.73 | L40: 45985 | M40: 46003.446 | N40: O4R1 | O40: Release_01 | Q40: 75678 | R40: WA-362 | S40: [Blip][S&D Colab.][R1] Autosserviço - Doc. do veículo - CRLV | T40: WHATSAPP;; | U40: O4R1;Release_01;
...

Sheet CONE
E1: O4R2 | F1: GOL | H1: TERA | J1: OPTIMUS | L1: NIVUS | N1: TAOS | P1: FUSCA | R1: UP
E2: ESCOPO | F2: =VLOOKUP(F1,'LEIA-ME'!$A:$B,2,0) -> VENDAS_ASSISTIDAS | H2: =VLOOKUP(H1,'LEIA-ME'!$A:$B,2,0) -> FATURAMENTO | J2: =VLOOKUP(J1,'LEIA-ME'!$A:$B,2,0) -> CONTRATOS | L2: =VLOOKUP(L1,'LEIA-ME'!$A:$B,2,0) -> COMERCIAL | N2: =VLOOKUP(N1,'LEIA-ME'!$A:$B,2,0) -> CREDITO | P2: =VLOOKUP(P1,'LEIA-ME'!$A:$B,2,0) -> SALESFORCE_PÓSVEND | R2: =VLOOKUP(R1,'LEIA-ME'!$A:$B,2,0) -> WHATSAPP
E3: Semana | F3: M | G3: P | H3: M | I3: P | J3: M | K3: P | L3: M | M3: P | N3: M | O3: P | P3: M | Q3: P | R3: M | S3: P
E4: 45936 | F4: ='GOL O4R2'!C15 -> 64 | G4: ='GOL O4R2'!D15 -> 64 | H4: ='TERA O4R2'!C15 -> 31 | I4: ='TERA O4R2'!D15 -> 31 | J4: ='OPTIMUS O4R2'!C15 -> 72 | K4: ='OPTIMUS O4R2'!D15 -> 72 | L4: ='NIVUS O4R2'!C15 -> 53 | M4: ='NIVUS O4R2'!D15 -> 53 | N4: ='TAOS O4R2'!C15 -> 16 | O4: ='TAOS O4R2'!D15 -> 16 | P4: ='FUSCA O4R2'!C15 -> 21 | Q4: ='FUSCA O4R2'!D15 -> 21 | R4: ='UP O4R2'!C15 -> 39 | S4: ='UP O4R2'!D15 -> 39
E5: =E4+7 -> 45943 | F5: ='GOL O4R2'!C16 -> 64 | G5: ='GOL O4R2'!D16 -> 64 | H5: ='TERA O4R2'!C16 -> 31 | I5: ='TERA O4R2'!D16 -> 31 | J5: ='OPTIMUS O4R2'!C16 -> 72 | K5: ='OPTIMUS O4R2'!D16 -> 72 | L5: ='NIVUS O4R2'!C16 -> 53 | M5: ='NIVUS O4R2'!D16 -> 53 | N5: ='TAOS O4R2'!C16 -> 16 | O5: ='TAOS O4R2'!D16 -> 16 | P5: ='FUSCA O4R2'!C16 -> 21 | Q5: ='FUSCA O4R2'!D16 -> 21 | R5: ='UP O4R2'!C16 -> 39 | S5: ='UP O4R2'!D16 -> 39
E6: =E5+7 -> 45950 | F6: ='GOL O4R2'!C17 -> 64 | G6: ='GOL O4R2'!D17 -> 64 | H6: ='TERA O4R2'!C17 -> 31 | I6: ='TERA O4R2'!D17 -> 31 | J6: ='OPTIMUS O4R2'!C17 -> 72 | K6: ='OPTIMUS O4R2'!D17 -> 72 | L6: ='NIVUS O4R2'!C17 -> 53 | M6: ='NIVUS O4R2'!D17 -> 53 | N6: ='TAOS O4R2'!C17 -> 16 | O6: ='TAOS O4R2'!D17 -> 16 | P6: ='FUSCA O4R2'!C17 -> 21 | Q6: ='FUSCA O4R2'!D17 -> 21 | R6: ='UP O4R2'!C17 -> 39 | S6: ='UP O4R2'!D17 -> 39
E7: =E6+7 -> 45957 | F7: ='GOL O4R2'!C18 -> 63 | G7: ='GOL O4R2'!D18 -> 63 | H7: ='TERA O4R2'!C18 -> 31 | I7: ='TERA O4R2'!D18 -> 31 | J7: ='OPTIMUS O4R2'!C18 -> 70 | K7: ='OPTIMUS O4R2'!D18 -> 70 | L7: ='NIVUS O4R2'!C18 -> 53 | M7: ='NIVUS O4R2'!D18 -> 53 | N7: ='TAOS O4R2'!C18 -> 16 | O7: ='TAOS O4R2'!D18 -> 16 | P7: ='FUSCA O4R2'!C18 -> 21 | Q7: ='FUSCA O4R2'!D18 -> 21 | R7: ='UP O4R2'!C18 -> 39 | S7: ='UP O4R2'!D18 -> 39
E8: =E7+7 -> 45964 | F8: ='GOL O4R2'!C19 -> 63 | G8: ='GOL O4R2'!D19 -> 63 | H8: ='TERA O4R2'!C19 -> 31 | I8: ='TERA O4R2'!D19 -> 31 | J8: ='OPTIMUS O4R2'!C19 -> 69 | K8: ='OPTIMUS O4R2'!D19 -> 69 | L8: ='NIVUS O4R2'!C19 -> 53 | M8: ='NIVUS O4R2'!D19 -> 53 | N8: ='TAOS O4R2'!C19 -> 16 | O8: ='TAOS O4R2'!D19 -> 16 | P8: ='FUSCA O4R2'!C19 -> 21 | Q8: ='FUSCA O4R2'!D19 -> 21 | R8: ='UP O4R2'!C19 -> 39 | S8: ='UP O4R2'!D19 -> 39
E9: =E8+7 -> 45971 | F9: ='GOL O4R2'!C20 -> 62 | G9: ='GOL O4R2'!D20 -> 62 | H9: ='TERA O4R2'!C20 -> 31 | I9: ='TERA O4R2'!D20 -> 31 | J9: ='OPTIMUS O4R2'!C20 -> 68 | K9: ='OPTIMUS O4R2'!D20 -> 68 | L9: ='NIVUS O4R2'!C20 -> 53 | M9: ='NIVUS O4R2'!D20 -> 53 | N9: ='TAOS O4R2'!C20 -> 16 | O9: ='TAOS O4R2'!D20 -> 16 | P9: ='FUSCA O4R2'!C20 -> 21 | Q9: ='FUSCA O4R2'!D20 -> 21 | R9: ='UP O4R2'!C20 -> 38 | S9: ='UP O4R2'!D20 -> 38
E10: =E9+7 -> 45978 | F10: ='GOL O4R2'!C21 -> 57 | G10: ='GOL O4R2'!D21 -> 57 | H10: ='TERA O4R2'!C21 -> 31 | I10: ='TERA O4R2'!D21 -> 31 | J10: ='OPTIMUS O4R2'!C21 -> 68 | K10: ='OPTIMUS O4R2'!D21 -> 68 | L10: ='NIVUS O4R2'!C21 -> 53 | M10: ='NIVUS O4R2'!D21 -> 53 | N10: ='TAOS O4R2'!C21 -> 16 | O10: ='TAOS O4R2'!D21 -> 16 | P10: ='FUSCA O4R2'!C21 -> 21 | Q10: ='FUSCA O4R2'!D21 -> 21 | R10: ='UP O4R2'!C21 -> 37 | S10: ='UP O4R2'!D21 -> 37
E11: =E10+7 -> 45985 | F11: ='GOL O4R2'!C22 -> 55 | G11: ='GOL O4R2'!D22 -> 55 | H11: ='TERA O4R2'!C22 -> 31 | I11: ='TERA O4R2'!D22 -> 31 | J11: ='OPTIMUS O4R2'!C22 -> 68 | K11: ='OPTIMUS O4R2'!D22 -> 68 | L11: ='NIVUS O4R2'!C22 -> 53 | M11: ='NIVUS O4R2'!D22 -> 53 | N11: ='TAOS O4R2'!C22 -> 16 | O11: ='TAOS O4R2'!D22 -> 16 | P11: ='FUSCA O4R2'!C22 -> 21 | Q11: ='FUSCA O4R2'!D22 -> 21 | R11: ='UP O4R2'!C22 -> 35 | S11: ='UP O4R2'!D22 -> 35
E12: =E11+7 -> 45992 | F12: ='GOL O4R2'!C23 -> 51 | G12: ='GOL O4R2'!D23 -> 51 | H12: ='TERA O4R2'!C23 -> 31 | I12: ='TERA O4R2'!D23 -> 31 | J12: ='OPTIMUS O4R2'!C23 -> 67 | K12: ='OPTIMUS O4R2'!D23 -> 67 | L12: ='NIVUS O4R2'!C23 -> 53 | M12: ='NIVUS O4R2'!D23 -> 53 | N12: ='TAOS O4R2'!C23 -> 16 | O12: ='TAOS O4R2'!D23 -> 16 | P12: ='FUSCA O4R2'!C23 -> 21 | Q12: ='FUSCA O4R2'!D23 -> 21 | R12: ='UP O4R2'!C23 -> 25 | S12: ='UP O4R2'!D23 -> 25
E13: =E12+7 -> 45999 | F13: ='GOL O4R2'!C24 -> 49 | G13: ='GOL O4R2'!D24 -> 49 | H13: ='TERA O4R2'!C24 -> 31 | I13: ='TERA O4R2'!D24 -> 31 | J13: ='OPTIMUS O4R2'!C24 -> 65 | K13: ='OPTIMUS O4R2'!D24 -> 65 | L13: ='NIVUS O4R2'!C24 -> 53 | M13: ='NIVUS O4R2'!D24 -> 53 | N13: ='TAOS O4R2'!C24 -> 16 | O13: ='TAOS O4R2'!D24 -> 16 | P13: ='FUSCA O4R2'!C24 -> 21 | Q13: ='FUSCA O4R2'!D24 -> 21 | R13: ='UP O4R2'!C24 -> 25 | S13: ='UP O4R2'!D24 -> 25
E14: =E13+7 -> 46006 | F14: ='GOL O4R2'!C25 -> 46 | G14: ='GOL O4R2'!D25 -> 46 | H14: ='TERA O4R2'!C25 -> 31 | I14: ='TERA O4R2'!D25 -> 31 | J14: ='OPTIMUS O4R2'!C25 -> 59 | K14: ='OPTIMUS O4R2'!D25 -> 59 | L14: ='NIVUS O4R2'!C25 -> 53 | M14: ='NIVUS O4R2'!D25 -> 53 | N14: ='TAOS O4R2'!C25 -> 16 | O14: ='TAOS O4R2'!D25 -> 16 | P14: ='FUSCA O4R2'!C25 -> 21 | Q14: ='FUSCA O4R2'!D25 -> 21 | R14: ='UP O4R2'!C25 -> 20 | S14: ='UP O4R2'!D25 -> 20
E15: =E14+7 -> 46013 | F15: ='GOL O4R2'!C26 -> 44 | G15: ='GOL O4R2'!D26 -> 44 | H15: ='TERA O4R2'!C26 -> 31 | I15: ='TERA O4R2'!D26 -> 31 | J15: ='OPTIMUS O4R2'!C26 -> 56 | K15: ='OPTIMUS O4R2'!D26 -> 56 | L15: ='NIVUS O4R2'!C26 -> 53 | M15: ='NIVUS O4R2'!D26 -> 53 | N15: ='TAOS O4R2'!C26 -> 15 | O15: ='TAOS O4R2'!D26 -> 15 | P15: ='FUSCA O4R2'!C26 -> 21 | Q15: ='FUSCA O4R2'!D26 -> 21 | R15: ='UP O4R2'!C26 -> 17 | S15: ='UP O4R2'!D26 -> 17
E16: =E15+7 -> 46020 | F16: ='GOL O4R2'!C27 -> 43 | G16: ='GOL O4R2'!D27 -> 43 | H16: ='TERA O4R2'!C27 -> 31 | I16: ='TERA O4R2'!D27 -> 31 | J16: ='OPTIMUS O4R2'!C27 -> 54 | K16: ='OPTIMUS O4R2'!D27 -> 54 | L16: ='NIVUS O4R2'!C27 -> 53 | M16: ='NIVUS O4R2'!D27 -> 53 | N16: ='TAOS O4R2'!C27 -> 15 | O16: ='TAOS O4R2'!D27 -> 15 | P16: ='FUSCA O4R2'!C27 -> 21 | Q16: ='FUSCA O4R2'!D27 -> 21 | R16: ='UP O4R2'!C27 -> 16 | S16: ='UP O4R2'!D27 -> 16
... E57: =E56+7 -> 46307 | F57: ='GOL O4R2'!C68 | G57: ='GOL O4R2'!D68 | H57: ='TERA O4R2'!C68 | I57: ='TERA O4R2'!D68 | J57: ='OPTIMUS O4R2'!C68 | K57: ='OPTIMUS O4R2'!D68 | L57: ='NIVUS O4R2'!C68 | M57: ='NIVUS O4R2'!D68 | N57: ='TAOS O4R2'!C68 | O57: ='TAOS O4R2'!D68 | P57: ='FUSCA O4R2'!C68 | Q57: ='FUSCA O4R2'!D68 | R57: ='UP O4R2'!C68 | S57: ='UP O4R2'!D68

Sheet GOL - TESTE
A1: Cone: baseado na nossa vazão, chegaremos na data alvo? O que cabe até data alvo?
B2: Quantidade de Épicos | D2: Épicos | E2: considerar apenas os épicos que estão no mapa de release
B3: Features | C3: 15 | D3: Story / Tarefa / Bug / Spike | E3: considerar o trabalho de todos os integrantes do time, inclsuive tasks de dívidas técnicas e automação
B4: Data início | C4: 46062 | D4: Primeria sprint da release
B5: Data fim esperada | C5: 46118 | D5: Data entregada release
B6: Melhor cenário | C6: 4 | D6: itens por semana | E6: considerar sempre as ultimas 4 sprints para atualizar os números
B7: Pior cenário | C7: 1 | D7: itens por semana | E7: considerar sempre as ultimas 4 sprints para atualizar os números
B8: Velocidade necessária | C8: 6 | D8: itens por semana
B9: Acompanhar a cada | C9: 7 | D9: dias
B11: Data do Início da Semana | C11: Se seguirmos nossa melhor vazão, quando entregamos? | D11: Se seguirmos nossa pior vazão, quando entregamos? | E11: Vazão ideal para atender à data | F11: Itens da sprint anterior que não foram concluídos | G11: Itens que entram em sprint pela primeira vez | H11: Itens que entraram na Sprint depois do planejamento, mas não são "Fura fila" | I11: Itens Fura-Fila que apareceram ao longo da Sprint | J11: Itens entregues na Sprint | K11: Itens que chegaram no backlog do time ao longo da semana, mas não na sprint | L11: Observações adicionais
B12: Não editar esses campos | G12: Preencher com os dados de cada semana
A13: Sprint | B13: Semana | C13: A fazer (melhor cenário) | D13: A fazer (pior cenário) | E13: A fazer (valocidade necessária) | F13: Itens Transbordo | G13: Itens Planejados (Planning) | H13: Itens não planejados na sprint | I13: (+) Expedite | J13: Realizado | K13: (+)(-) Escopo pro time | L13: OBSERVAÇÕES
B14: =C4 -> 46062 | C14: =$C$3 -> 15 | D14: =$C$3 -> 15 | E14: =$C$3 -> 15
A15: Sprint 11 | B15: =B14+$C$9 -> 46069 | C15: =IF(OR(C14="",C14=0),"",IF(ISBLANK($J14),IF(C14+$K14+$I14-$C$6<=0,IF(AND(C14>0,C14<>""),0,""),C14+$K14+$I14-$C$6),IF((C14-$J14)+$K14+$I14<=0,IF(AND(C14>0,C14<>""),0,""),(C14-$J14)+$K14+$I14))) -> 11 | D15: =IF(OR(D14="",D14=0),"",IF(ISBLANK($J14),IF(D14+$K14+$I14-$C$7<=0,IF(AND(D14>0,D14<>""),0,""),D14+$K14+$I14-$C$7),IF((D14-$J14)+$K14+$I14<=0,IF(AND(D14>0,D14<>""),0,""),(D14-$J14)+$K14+$I14))) -> 14 | E15: =IF(OR(E14="",E14=0),"",IF(ISBLANK($J14),IF(E14+$K14+$I14-$C$8<=0,IF(AND(E14>0,E14<>""),0,""),E14+$K14+$I14-$C$8),IF((E14-$J14)+$K14+$I14<=0,IF(AND(E14>0,E14<>""),0,""),(E14-$J14)+$K14+$I14))) -> 9 | F15: =IF(J14="","",IF(G14+F14+H14+I14-J14<0,0,G14+F14+H14+I14-J14))
A16: Sprint 12 | B16: =B15+$C$9 -> 46076 | C16: =IF(OR(C15="",C15=0),"",IF(ISBLANK(J15),IF(C15+K15+I15-$C$6<=0,IF(AND(C15>0,C15<>""),0,""),C15+K15+I15-$C$6),IF((C15-J15)+K15+I15<=0,IF(AND(C15>0,C15<>""),0,""),(C15-J15)+K15+I15))) -> 7 | D16: =IF(OR(D15="",D15=0),"",IF(ISBLANK($J15),IF(D15+$K15+$I15-$C$7<=0,IF(AND(D15>0,D15<>""),0,""),D15+$K15+$I15-$C$7),IF((D15-$J15)+$K15+$I15<=0,IF(AND(D15>0,D15<>""),0,""),(D15-$J15)+$K15+$I15))) -> 13 | E16: =IF(OR(E15="",E15=0),"",IF(ISBLANK($J15),IF(E15+$K15+$I15-$C$8<=0,IF(AND(E15>0,E15<>""),0,""),E15+$K15+$I15-$C$8),IF((E15-$J15)+$K15+$I15<=0,IF(AND(E15>0,E15<>""),0,""),(E15-$J15)+$K15+$I15))) -> 3 | F16: =IF(J15="","",IF(G15+F15+H15+I15-J15<0,0,G15+F15+H15+I15-J15))
A17: Sprint 13 | B17: =B16+$C$9 -> 46083 | C17: =IF(OR(C16="",C16=0),"",IF(ISBLANK(J16),IF(C16+K16+I16-$C$6<=0,IF(AND(C16>0,C16<>""),0,""),C16+K16+I16-$C$6),IF((C16-J16)+K16+I16<=0,IF(AND(C16>0,C16<>""),0,""),(C16-J16)+K16+I16))) -> 3 | D17: =IF(OR(D16="",D16=0),"",IF(ISBLANK($J16),IF(D16+$K16+$I16-$C$7<=0,IF(AND(D16>0,D16<>""),0,""),D16+$K16+$I16-$C$7),IF((D16-$J16)+$K16+$I16<=0,IF(AND(D16>0,D16<>""),0,""),(D16-$J16)+$K16+$I16))) -> 12 | E17: =IF(OR(E16="",E16=0),"",IF(ISBLANK($J16),IF(E16+$K16+$I16-$C$8<=0,IF(AND(E16>0,E16<>""),0,""),E16+$K16+$I16-$C$8),IF((E16-$J16)+$K16+$I16<=0,IF(AND(E16>0,E16<>""),0,""),(E16-$J16)+$K16+$I16))) -> 0 | F17: =IF(J16="","",IF(G16+F16+H16+I16-J16<0,0,G16+F16+H16+I16-J16))
A18: Sprint 14 | B18: =B17+$C$9 -> 46090 | C18: =IF(OR(C17="",C17=0),"",IF(ISBLANK(J17),IF(C17+K17+I17-$C$6<=0,IF(AND(C17>0,C17<>""),0,""),C17+K17+I17-$C$6),IF((C17-J17)+K17+I17<=0,IF(AND(C17>0,C17<>""),0,""),(C17-J17)+K17+I17))) -> 0 | D18: =IF(OR(D17="",D17=0),"",IF(ISBLANK($J17),IF(D17+$K17+$I17-$C$7<=0,IF(AND(D17>0,D17<>""),0,""),D17+$K17+$I17-$C$7),IF((D17-$J17)+$K17+$I17<=0,IF(AND(D17>0,D17<>""),0,""),(D17-$J17)+$K17+$I17))) -> 11 | E18: =IF(OR(E17="",E17=0),"",IF(ISBLANK($J17),IF(E17+$K17+$I17-$C$8<=0,IF(AND(E17>0,E17<>""),0,""),E17+$K17+$I17-$C$8),IF((E17-$J17)+$K17+$I17<=0,IF(AND(E17>0,E17<>""),0,""),(E17-$J17)+$K17+$I17))) | F18: =IF(J17="","",IF(G17+F17+H17+I17-J17<0,0,G17+F17+H17+I17-J17))
A19: Sprint 15 | B19: =B18+$C$9 -> 46097 | C19: =IF(OR(C18="",C18=0),"",IF(ISBLANK(J18),IF(C18+K18+I18-$C$6<=0,IF(AND(C18>0,C18<>""),0,""),C18+K18+I18-$C$6),IF((C18-J18)+K18+I18<=0,IF(AND(C18>0,C18<>""),0,""),(C18-J18)+K18+I18))) | D19: =IF(OR(D18="",D18=0),"",IF(ISBLANK($J18),IF(D18+$K18+$I18-$C$7<=0,IF(AND(D18>0,D18<>""),0,""),D18+$K18+$I18-$C$7),IF((D18-$J18)+$K18+$I18<=0,IF(AND(D18>0,D18<>""),0,""),(D18-$J18)+$K18+$I18))) -> 10 | E19: =IF(OR(E18="",E18=0),"",IF(ISBLANK($J18),IF(E18+$K18+$I18-$C$8<=0,IF(AND(E18>0,E18<>""),0,""),E18+$K18+$I18-$C$8),IF((E18-$J18)+$K18+$I18<=0,IF(AND(E18>0,E18<>""),0,""),(E18-$J18)+$K18+$I18))) | F19: =IF(J18="","",IF(G18+F18+H18+I18-J18<0,0,G18+F18+H18+I18-J18))
A20: Sprint 16 | B20: =B19+$C$9 -> 46104 | C20: =IF(OR(C19="",C19=0),"",IF(ISBLANK(J19),IF(C19+K19+I19-$C$6<=0,IF(AND(C19>0,C19<>""),0,""),C19+K19+I19-$C$6),IF((C19-J19)+K19+I19<=0,IF(AND(C19>0,C19<>""),0,""),(C19-J19)+K19+I19))) | D20: =IF(OR(D19="",D19=0),"",IF(ISBLANK($J19),IF(D19+$K19+$I19-$C$7<=0,IF(AND(D19>0,D19<>""),0,""),D19+$K19+$I19-$C$7),IF((D19-$J19)+$K19+$I19<=0,IF(AND(D19>0,D19<>""),0,""),(D19-$J19)+$K19+$I19))) -> 9 | E20: =IF(OR(E19="",E19=0),"",IF(ISBLANK($J19),IF(E19+$K19+$I19-$C$8<=0,IF(AND(E19>0,E19<>""),0,""),E19+$K19+$I19-$C$8),IF((E19-$J19)+$K19+$I19<=0,IF(AND(E19>0,E19<>""),0,""),(E19-$J19)+$K19+$I19))) | F20: =IF(J19="","",IF(G19+F19+H19+I19-J19<0,0,G19+F19+H19+I19-J19))
A21: Sprint 17 | B21: =B20+$C$9 -> 46111 | C21: =IF(OR(C20="",C20=0),"",IF(ISBLANK(J20),IF(C20+K20+I20-$C$6<=0,IF(AND(C20>0,C20<>""),0,""),C20+K20+I20-$C$6),IF((C20-J20)+K20+I20<=0,IF(AND(C20>0,C20<>""),0,""),(C20-J20)+K20+I20))) | D21: =IF(OR(D20="",D20=0),"",IF(ISBLANK($J20),IF(D20+$K20+$I20-$C$7<=0,IF(AND(D20>0,D20<>""),0,""),D20+$K20+$I20-$C$7),IF((D20-$J20)+$K20+$I20<=0,IF(AND(D20>0,D20<>""),0,""),(D20-$J20)+$K20+$I20))) -> 8 | E21: =IF(OR(E20="",E20=0),"",IF(ISBLANK($J20),IF(E20+$K20+$I20-$C$8<=0,IF(AND(E20>0,E20<>""),0,""),E20+$K20+$I20-$C$8),IF((E20-$J20)+$K20+$I20<=0,IF(AND(E20>0,E20<>""),0,""),(E20-$J20)+$K20+$I20))) | F21: =IF(J20="","",IF(G20+F20+H20+I20-J20<0,0,G20+F20+H20+I20-J20))
A22: Sprint 18 | B22: =B21+$C$9 -> 46118 | C22: =IF(OR(C21="",C21=0),"",IF(ISBLANK(J21),IF(C21+K21+I21-$C$6<=0,IF(AND(C21>0,C21<>""),0,""),C21+K21+I21-$C$6),IF((C21-J21)+K21+I21<=0,IF(AND(C21>0,C21<>""),0,""),(C21-J21)+K21+I21))) | D22: =IF(OR(D21="",D21=0),"",IF(ISBLANK($J21),IF(D21+$K21+$I21-$C$7<=0,IF(AND(D21>0,D21<>""),0,""),D21+$K21+$I21-$C$7),IF((D21-$J21)+$K21+$I21<=0,IF(AND(D21>0,D21<>""),0,""),(D21-$J21)+$K21+$I21))) -> 7 | E22: =IF(OR(E21="",E21=0),"",IF(ISBLANK($J21),IF(E21+$K21+$I21-$C$8<=0,IF(AND(E21>0,E21<>""),0,""),E21+$K21+$I21-$C$8),IF((E21-$J21)+$K21+$I21<=0,IF(AND(E21>0,E21<>""),0,""),(E21-$J21)+$K21+$I21))) | F22: =IF(J21="","",IF(G21+F21+H21+I21-J21<0,0,G21+F21+H21+I21-J21))
A23: Sprint 19 | B23: =B22+$C$9 -> 46125 | C23: =IF(OR(C22="",C22=0),"",IF(ISBLANK(J22),IF(C22+K22+I22-$C$6<=0,IF(AND(C22>0,C22<>""),0,""),C22+K22+I22-$C$6),IF((C22-J22)+K22+I22<=0,IF(AND(C22>0,C22<>""),0,""),(C22-J22)+K22+I22))) | D23: =IF(OR(D22="",D22=0),"",IF(ISBLANK($J22),IF(D22+$K22+$I22-$C$7<=0,IF(AND(D22>0,D22<>""),0,""),D22+$K22+$I22-$C$7),IF((D22-$J22)+$K22+$I22<=0,IF(AND(D22>0,D22<>""),0,""),(D22-$J22)+$K22+$I22))) -> 6 | E23: =IF(OR(E22="",E22=0),"",IF(ISBLANK($J22),IF(E22+$K22+$I22-$C$8<=0,IF(AND(E22>0,E22<>""),0,""),E22+$K22+$I22-$C$8),IF((E22-$J22)+$K22+$I22<=0,IF(AND(E22>0,E22<>""),0,""),(E22-$J22)+$K22+$I22))) | F23: =IF(J22="","",IF(G22+F22+H22+I22-J22<0,0,G22+F22+H22+I22-J22))
A24: Sprint 20 | B24: =B23+$C$9 -> 46132 | C24: =IF(OR(C23="",C23=0),"",IF(ISBLANK(J23),IF(C23+K23+I23-$C$6<=0,IF(AND(C23>0,C23<>""),0,""),C23+K23+I23-$C$6),IF((C23-J23)+K23+I23<=0,IF(AND(C23>0,C23<>""),0,""),(C23-J23)+K23+I23))) | D24: =IF(OR(D23="",D23=0),"",IF(ISBLANK($J23),IF(D23+$K23+$I23-$C$7<=0,IF(AND(D23>0,D23<>""),0,""),D23+$K23+$I23-$C$7),IF((D23-$J23)+$K23+$I23<=0,IF(AND(D23>0,D23<>""),0,""),(D23-$J23)+$K23+$I23))) -> 5 | E24: =IF(OR(E23="",E23=0),"",IF(ISBLANK($J23),IF(E23+$K23+$I23-$C$8<=0,IF(AND(E23>0,E23<>""),0,""),E23+$K23+$I23-$C$8),IF((E23-$J23)+$K23+$I23<=0,IF(AND(E23>0,E23<>""),0,""),(E23-$J23)+$K23+$I23))) | F24: =IF(J23="","",IF(G23+F23+H23+I23-J23<0,0,G23+F23+H23+I23-J23))
A25: Sprint 21 | B25: =B24+$C$9 -> 46139 | C25: =IF(OR(C24="",C24=0),"",IF(ISBLANK(J24),IF(C24+K24+I24-$C$6<=0,IF(AND(C24>0,C24<>""),0,""),C24+K24+I24-$C$6),IF((C24-J24)+K24+I24<=0,IF(AND(C24>0,C24<>""),0,""),(C24-J24)+K24+I24))) | D25: =IF(OR(D24="",D24=0),"",IF(ISBLANK($J24),IF(D24+$K24+$I24-$C$7<=0,IF(AND(D24>0,D24<>""),0,""),D24+$K24+$I24-$C$7),IF((D24-$J24)+$K24+$I24<=0,IF(AND(D24>0,D24<>""),0,""),(D24-$J24)+$K24+$I24))) -> 4 | E25: =IF(OR(E24="",E24=0),"",IF(ISBLANK($J24),IF(E24+$K24+$I24-$C$8<=0,IF(AND(E24>0,E24<>""),0,""),E24+$K24+$I24-$C$8),IF((E24-$J24)+$K24+$I24<=0,IF(AND(E24>0,E24<>""),0,""),(E24-$J24)+$K24+$I24))) | F25: =IF(J24="","",IF(G24+F24+H24+I24-J24<0,0,G24+F24+H24+I24-J24))
A26: Sprint 22 | B26: =B25+$C$9 -> 46146 | C26: =IF(OR(C25="",C25=0),"",IF(ISBLANK(J25),IF(C25+K25+I25-$C$6<=0,IF(AND(C25>0,C25<>""),0,""),C25+K25+I25-$C$6),IF((C25-J25)+K25+I25<=0,IF(AND(C25>0,C25<>""),0,""),(C25-J25)+K25+I25))) | D26: =IF(OR(D25="",D25=0),"",IF(ISBLANK($J25),IF(D25+$K25+$I25-$C$7<=0,IF(AND(D25>0,D25<>""),0,""),D25+$K25+$I25-$C$7),IF((D25-$J25)+$K25+$I25<=0,IF(AND(D25>0,D25<>""),0,""),(D25-$J25)+$K25+$I25))) -> 3 | E26: =IF(OR(E25="",E25=0),"",IF(ISBLANK($J25),IF(E25+$K25+$I25-$C$8<=0,IF(AND(E25>0,E25<>""),0,""),E25+$K25+$I25-$C$8),IF((E25-$J25)+$K25+$I25<=0,IF(AND(E25>0,E25<>""),0,""),(E25-$J25)+$K25+$I25))) | F26: =IF(J25="","",IF(G25+F25+H25+I25-J25<0,0,G25+F25+H25+I25-J25))
A27: Sprint 23 | B27: =B26+$C$9 -> 46153 | C27: =IF(OR(C26="",C26=0),"",IF(ISBLANK(J26),IF(C26+K26+I26-$C$6<=0,IF(AND(C26>0,C26<>""),0,""),C26+K26+I26-$C$6),IF((C26-J26)+K26+I26<=0,IF(AND(C26>0,C26<>""),0,""),(C26-J26)+K26+I26))) | D27: =IF(OR(D26="",D26=0),"",IF(ISBLANK($J26),IF(D26+$K26+$I26-$C$7<=0,IF(AND(D26>0,D26<>""),0,""),D26+$K26+$I26-$C$7),IF((D26-$J26)+$K26+$I26<=0,IF(AND(D26>0,D26<>""),0,""),(D26-$J26)+$K26+$I26))) -> 2 | E27: =IF(OR(E26="",E26=0),"",IF(ISBLANK($J26),IF(E26+$K26+$I26-$C$8<=0,IF(AND(E26>0,E26<>""),0,""),E26+$K26+$I26-$C$8),IF((E26-$J26)+$K26+$I26<=0,IF(AND(E26>0,E26<>""),0,""),(E26-$J26)+$K26+$I26))) | F27: =IF(J26="","",IF(G26+F26+H26+I26-J26<0,0,G26+F26+H26+I26-J26))
... A30: Sprint 26 | B30: =B29+$C$9 -> 46174 | C30: =IF(OR(C29="",C29=0),"",IF(ISBLANK(J29),IF(C29+K29+I29-$C$6<=0,IF(AND(C29>0,C29<>""),0,""),C29+K29+I29-$C$6),IF((C29-J29)+K29+I29<=0,IF(AND(C29>0,C29<>""),0,""),(C29-J29)+K29+I29))) | D30: =IF(OR(D29="",D29=0),"",IF(ISBLANK($J29),IF(D29+$K29+$I29-$C$7<=0,IF(AND(D29>0,D29<>""),0,""),D29+$K29+$I29-$C$7),IF((D29-$J29)+$K29+$I29<=0,IF(AND(D29>0,D29<>""),0,""),(D29-$J29)+$K29+$I29))) | E30: =IF(OR(E29="",E29=0),"",IF(ISBLANK($J29),IF(E29+$K29+$I29-$C$8<=0,IF(AND(E29>0,E29<>""),0,""),E29+$K29+$I29-$C$8),IF((E29-$J29)+$K29+$I29<=0,IF(AND(E29>0,E29<>""),0,""),(E29-$J29)+$K29+$I29))) | F30: =IF(J29="","",IF(G29+F29+H29+I29-J29<0,0,G29+F29+H29+I29-J29))
B31: =B30+$C$9 -> 46181 | C31: =IF(OR(C30="",C30=0),"",IF(ISBLANK(J30),IF(C30+K30+I30-$C$6<=0,IF(AND(C30>0,C30<>""),0,""),C30+K30+I30-$C$6),IF((C30-J30)+K30+I30<=0,IF(AND(C30>0,C30<>""),0,""),(C30-J30)+K30+I30))) | D31: =IF(OR(D30="",D30=0),"",IF(ISBLANK($J30),IF(D30+$K30+$I30-$C$7<=0,IF(AND(D30>0,D30<>""),0,""),D30+$K30+$I30-$C$7),IF((D30-$J30)+$K30+$I30<=0,IF(AND(D30>0,D30<>""),0,""),(D30-$J30)+$K30+$I30))) | E31: =IF(OR(E30="",E30=0),"",IF(ISBLANK($J30),IF(E30+$K30+$I30-$C$8<=0,IF(AND(E30>0,E30<>""),0,""),E30+$K30+$I30-$C$8),IF((E30-$J30)+$K30+$I30<=0,IF(AND(E30>0,E30<>""),0,""),(E30-$J30)+$K30+$I30))) | F31: =IF(J30="","",IF(G30+F30+H30+I30-J30<0,0,G30+F30+H30+I30-J30))
B32: =B31+$C$9 -> 46188 | C32: =IF(OR(C31="",C31=0),"",IF(ISBLANK(J31),IF(C31+K31+I31-$C$6<=0,IF(AND(C31>0,C31<>""),0,""),C31+K31+I31-$C$6),IF((C31-J31)+K31+I31<=0,IF(AND(C31>0,C31<>""),0,""),(C31-J31)+K31+I31))) | D32: =IF(OR(D31="",D31=0),"",IF(ISBLANK($J31),IF(D31+$K31+$I31-$C$7<=0,IF(AND(D31>0,D31<>""),0,""),D31+$K31+$I31-$C$7),IF((D31-$J31)+$K31+$I31<=0,IF(AND(D31>0,D31<>""),0,""),(D31-$J31)+$K31+$I31))) | E32: =IF(OR(E31="",E31=0),"",IF(ISBLANK($J31),IF(E31+$K31+$I31-$C$8<=0,IF(AND(E31>0,E31<>""),0,""),E31+$K31+$I31-$C$8),IF((E31-$J31)+$K31+$I31<=0,IF(AND(E31>0,E31<>""),0,""),(E31-$J31)+$K31+$I31))) | F32: =IF(J31="","",IF(G31+F31+H31+I31-J31<0,0,G31+F31+H31+I31-J31))
B33: =B32+$C$9 -> 46195 | C33: =IF(OR(C32="",C32=0),"",IF(ISBLANK(J32),IF(C32+K32+I32-$C$6<=0,IF(AND(C32>0,C32<>""),0,""),C32+K32+I32-$C$6),IF((C32-J32)+K32+I32<=0,IF(AND(C32>0,C32<>""),0,""),(C32-J32)+K32+I32))) | D33: =IF(OR(D32="",D32=0),"",IF(ISBLANK($J32),IF(D32+$K32+$I32-$C$7<=0,IF(AND(D32>0,D32<>""),0,""),D32+$K32+$I32-$C$7),IF((D32-$J32)+$K32+$I32<=0,IF(AND(D32>0,D32<>""),0,""),(D32-$J32)+$K32+$I32))) | E33: =IF(OR(E32="",E32=0),"",IF(ISBLANK($J32),IF(E32+$K32+$I32-$C$8<=0,IF(AND(E32>0,E32<>""),0,""),E32+$K32+$I32-$C$8),IF((E32-$J32)+$K32+$I32<=0,IF(AND(E32>0,E32<>""),0,""),(E32-$J32)+$K32+$I32))) | F33: =IF(J32="","",IF(G32+F32+H32+I32-J32<0,0,G32+F32+H32+I32-J32))
B34: =B33+$C$9 -> 46202 | C34: =IF(OR(C33="",C33=0),"",IF(ISBLANK(J33),IF(C33+K33+I33-$C$6<=0,IF(AND(C33>0,C33<>""),0,""),C33+K33+I33-$C$6),IF((C33-J33)+K33+I33<=0,IF(AND(C33>0,C33<>""),0,""),(C33-J33)+K33+I33))) | D34: =IF(OR(D33="",D33=0),"",IF(ISBLANK($J33),IF(D33+$K33+$I33-$C$7<=0,IF(AND(D33>0,D33<>""),0,""),D33+$K33+$I33-$C$7),IF((D33-$J33)+$K33+$I33<=0,IF(AND(D33>0,D33<>""),0,""),(D33-$J33)+$K33+$I33))) | E34: =IF(OR(E33="",E33=0),"",IF(ISBLANK($J33),IF(E33+$K33+$I33-$C$8<=0,IF(AND(E33>0,E33<>""),0,""),E33+$K33+$I33-$C$8),IF((E33-$J33)+$K33+$I33<=0,IF(AND(E33>0,E33<>""),0,""),(E33-$J33)+$K33+$I33))) | F34: =IF(J33="","",IF(G33+F33+H33+I33-J33<0,0,G33+F33+H33+I33-J33))
B35: =B34+$C$9 -> 46209 | C35: =IF(OR(C34="",C34=0),"",IF(ISBLANK(J34),IF(C34+K34+I34-$C$6<=0,IF(AND(C34>0,C34<>""),0,""),C34+K34+I34-$C$6),IF((C34-J34)+K34+I34<=0,IF(AND(C34>0,C34<>""),0,""),(C34-J34)+K34+I34))) | D35: =IF(OR(D34="",D34=0),"",IF(ISBLANK($J34),IF(D34+$K34+$I34-$C$7<=0,IF(AND(D34>0,D34<>""),0,""),D34+$K34+$I34-$C$7),IF((D34-$J34)+$K34+$I34<=0,IF(AND(D34>0,D34<>""),0,""),(D34-$J34)+$K34+$I34))) | E35: =IF(OR(E34="",E34=0),"",IF(ISBLANK($J34),IF(E34+$K34+$I34-$C$8<=0,IF(AND(E34>0,E34<>""),0,""),E34+$K34+$I34-$C$8),IF((E34-$J34)+$K34+$I34<=0,IF(AND(E34>0,E34<>""),0,""),(E34-$J34)+$K34+$I34))) | F35: =IF(J34="","",IF(G34+F34+H34+I34-J34<0,0,G34+F34+H34+I34-J34))
B36: =B35+$C$9 -> 46216 | C36: =IF(OR(C35="",C35=0),"",IF(ISBLANK(J35),IF(C35+K35+I35-$C$6<=0,IF(AND(C35>0,C35<>""),0,""),C35+K35+I35-$C$6),IF((C35-J35)+K35+I35<=0,IF(AND(C35>0,C35<>""),0,""),(C35-J35)+K35+I35))) | D36: =IF(OR(D35="",D35=0),"",IF(ISBLANK($J35),IF(D35+$K35+$I35-$C$7<=0,IF(AND(D35>0,D35<>""),0,""),D35+$K35+$I35-$C$7),IF((D35-$J35)+$K35+$I35<=0,IF(AND(D35>0,D35<>""),0,""),(D35-$J35)+$K35+$I35))) | E36: =IF(OR(E35="",E35=0),"",IF(ISBLANK($J35),IF(E35+$K35+$I35-$C$8<=0,IF(AND(E35>0,E35<>""),0,""),E35+$K35+$I35-$C$8),IF((E35-$J35)+$K35+$I35<=0,IF(AND(E35>0,E35<>""),0,""),(E35-$J35)+$K35+$I35))) | F36: =IF(J35="","",IF(G35+F35+H35+I35-J35<0,0,G35+F35+H35+I35-J35))
B37: =B36+$C$9 -> 46223 | C37: =IF(OR(C36="",C36=0),"",IF(ISBLANK(J36),IF(C36+K36+I36-$C$6<=0,IF(AND(C36>0,C36<>""),0,""),C36+K36+I36-$C$6),IF((C36-J36)+K36+I36<=0,IF(AND(C36>0,C36<>""),0,""),(C36-J36)+K36+I36))) | D37: =IF(OR(D36="",D36=0),"",IF(ISBLANK($J36),IF(D36+$K36+$I36-$C$7<=0,IF(AND(D36>0,D36<>""),0,""),D36+$K36+$I36-$C$7),IF((D36-$J36)+$K36+$I36<=0,IF(AND(D36>0,D36<>""),0,""),(D36-$J36)+$K36+$I36))) | E37: =IF(OR(E36="",E36=0),"",IF(ISBLANK($J36),IF(E36+$K36+$I36-$C$8<=0,IF(AND(E36>0,E36<>""),0,""),E36+$K36+$I36-$C$8),IF((E36-$J36)+$K36+$I36<=0,IF(AND(E36>0,E36<>""),0,""),(E36-$J36)+$K36+$I36))) | F37: =IF(J36="","",IF(G36+F36+H36+I36-J36<0,0,G36+F36+H36+I36-J36))
B38: =B37+$C$9 -> 46230 | C38: =IF(OR(C37="",C37=0),"",IF(ISBLANK(J37),IF(C37+K37+I37-$C$6<=0,IF(AND(C37>0,C37<>""),0,""),C37+K37+I37-$C$6),IF((C37-J37)+K37+I37<=0,IF(AND(C37>0,C37<>""),0,""),(C37-J37)+K37+I37))) | D38: =IF(OR(D37="",D37=0),"",IF(ISBLANK($J37),IF(D37+$K37+$I37-$C$7<=0,IF(AND(D37>0,D37<>""),0,""),D37+$K37+$I37-$C$7),IF((D37-$J37)+$K37+$I37<=0,IF(AND(D37>0,D37<>""),0,""),(D37-$J37)+$K37+$I37))) | E38: =IF(OR(E37="",E37=0),"",IF(ISBLANK($J37),IF(E37+$K37+$I37-$C$8<=0,IF(AND(E37>0,E37<>""),0,""),E37+$K37+$I37-$C$8),IF((E37-$J37)+$K37+$I37<=0,IF(AND(E37>0,E37<>""),0,""),(E37-$J37)+$K37+$I37))) | F38: =IF(J37="","",IF(G37+F37+H37+I37-J37<0,0,G37+F37+H37+I37-J37))
B39: =B38+$C$9 -> 46237 | C39: =IF(OR(C38="",C38=0),"",IF(ISBLANK(J38),IF(C38+K38+I38-$C$6<=0,IF(AND(C38>0,C38<>""),0,""),C38+K38+I38-$C$6),IF((C38-J38)+K38+I38<=0,IF(AND(C38>0,C38<>""),0,""),(C38-J38)+K38+I38))) | D39: =IF(OR(D38="",D38=0),"",IF(ISBLANK($J38),IF(D38+$K38+$I38-$C$7<=0,IF(AND(D38>0,D38<>""),0,""),D38+$K38+$I38-$C$7),IF((D38-$J38)+$K38+$I38<=0,IF(AND(D38>0,D38<>""),0,""),(D38-$J38)+$K38+$I38))) | E39: =IF(OR(E38="",E38=0),"",IF(ISBLANK($J38),IF(E38+$K38+$I38-$C$8<=0,IF(AND(E38>0,E38<>""),0,""),E38+$K38+$I38-$C$8),IF((E38-$J38)+$K38+$I38<=0,IF(AND(E38>0,E38<>""),0,""),(E38-$J38)+$K38+$I38))) | F39: =IF(J38="","",IF(G38+F38+H38+I38-J38<0,0,G38+F38+H38+I38-J38))
